Traceback (most recent call last):
  File "/Users/jimenezm/miniforge3/envs/pydap_docs/lib/python3.11/site-packages/jupyter_cache/executors/utils.py", line 58, in single_nb_execution
    executenb(
  File "/Users/jimenezm/miniforge3/envs/pydap_docs/lib/python3.11/site-packages/nbclient/client.py", line 1319, in execute
    return NotebookClient(nb=nb, resources=resources, km=km, **kwargs).execute()
           ^^^^^^^^^^^^^^^^^^^^^^^^^^^^^^^^^^^^^^^^^^^^^^^^^^^^^^^^^^^^^^^^^^^^^
  File "/Users/jimenezm/miniforge3/envs/pydap_docs/lib/python3.11/site-packages/jupyter_core/utils/__init__.py", line 165, in wrapped
    return loop.run_until_complete(inner)
           ^^^^^^^^^^^^^^^^^^^^^^^^^^^^^^
  File "/Users/jimenezm/miniforge3/envs/pydap_docs/lib/python3.11/asyncio/base_events.py", line 654, in run_until_complete
    return future.result()
           ^^^^^^^^^^^^^^^
  File "/Users/jimenezm/miniforge3/envs/pydap_docs/lib/python3.11/site-packages/nbclient/client.py", line 709, in async_execute
    await self.async_execute_cell(
  File "/Users/jimenezm/miniforge3/envs/pydap_docs/lib/python3.11/site-packages/nbclient/client.py", line 1062, in async_execute_cell
    await self._check_raise_for_error(cell, cell_index, exec_reply)
  File "/Users/jimenezm/miniforge3/envs/pydap_docs/lib/python3.11/site-packages/nbclient/client.py", line 918, in _check_raise_for_error
    raise CellExecutionError.from_cell_and_msg(cell, exec_reply_content)
nbclient.exceptions.CellExecutionError: An error occurred while executing the following cell:
------------------
dataset['/gt1r/bckgrd_atlas/bckgrd_int_height'].dimensions # dimensions of the variable
------------------


[31m---------------------------------------------------------------------------[39m
[31mKeyError[39m                                  Traceback (most recent call last)
[36mFile [39m[32m~/miniforge3/envs/pydap_docs/lib/python3.11/site-packages/pydap/model.py:244[39m, in [36mDapType.__getattr__[39m[34m(self, attr)[39m
[32m    243[39m [38;5;28;01mtry[39;00m:
[32m--> [39m[32m244[39m     [38;5;28;01mreturn[39;00m [38;5;28;43mself[39;49m[43m.[49m[43mattributes[49m[43m[[49m[43mattr[49m[43m][49m
[32m    245[39m [38;5;28;01mexcept[39;00m ([38;5;167;01mKeyError[39;00m, [38;5;167;01mTypeError[39;00m):

[31mKeyError[39m: 'dimensions'

During handling of the above exception, another exception occurred:

[31mAttributeError[39m                            Traceback (most recent call last)
[36mCell[39m[36m [39m[32mIn[6][39m[32m, line 1[39m
[32m----> [39m[32m1[39m [43mdataset[49m[43m[[49m[33;43m'[39;49m[33;43m/gt1r/bckgrd_atlas/bckgrd_int_height[39;49m[33;43m'[39;49m[43m][49m[43m.[49m[43mdimensions[49m [38;5;66;03m# dimensions of the variable[39;00m

[36mFile [39m[32m~/miniforge3/envs/pydap_docs/lib/python3.11/site-packages/pydap/model.py:246[39m, in [36mDapType.__getattr__[39m[34m(self, attr)[39m
[32m    244[39m     [38;5;28;01mreturn[39;00m [38;5;28mself[39m.attributes[attr]
[32m    245[39m [38;5;28;01mexcept[39;00m ([38;5;167;01mKeyError[39;00m, [38;5;167;01mTypeError[39;00m):
[32m--> [39m[32m246[39m     [38;5;28;01mraise[39;00m [38;5;167;01mAttributeError[39;00m(
[32m    247[39m         [33m"[39m[33m'[39m[38;5;132;01m%s[39;00m[33m'[39m[33m object has no attribute [39m[33m'[39m[38;5;132;01m%s[39;00m[33m'[39m[33m"[39m % ([38;5;28mtype[39m([38;5;28mself[39m), attr)
[32m    248[39m     )

[31mAttributeError[39m: '<class 'pydap.model.BaseType'>' object has no attribute 'dimensions'

